Workbook
Name \0: #REF!
Name \a: #REF!
Name \b: #REF!
Name \m: [1]Laco1!#REF!
Name \q: [1]Laco1!#REF!
Name \s: #REF!
Name _1_0o: #REF!
Name _10_0m: #REF!
Name _11_0s: #REF!
Name _12f: #REF!
Name _13l: #REF!
Name _14m: #REF!
Name _15m: #REF!
Name _16s: #REF!
Name _2o: #REF!
Name _3_0n: #REF!
Name _4n: #REF!
Name _5_0g: #REF!
Name _6g: #REF!
Name _7_0f: #REF!
Name _8_0l: #REF!
Name _9_0m: #REF!
Name _apr1: #REF!
Name _AQP45: #REF!
Name _B559000: [2]MARcomFEV01!$B$5925:$IV$10908
Name _B559000: [3]MARcomFEV01!$B$5925:$IV$10908
Name _Cil48: #REF!
Name _DAT1: #REF!
Name _DAT10: #REF!
Name _DAT11: #REF!
Name _DAT11: '[4]BASE PFC'!#REF!
Name _DAT12: #REF!
Name _DAT12: '[4]BASE PFC'!#REF!
Name _DAT13: #REF!
Name _DAT14: #REF!
Name _DAT14: '[4]BASE PFC'!#REF!
Name _DAT15: #REF!
Name _DAT15: '[4]BASE PFC'!#REF!
Name _DAT16: #REF!
Name _DAT16: '[4]BASE PFC'!#REF!
Name _DAT17: #REF!
Name _DAT17: '[4]BASE PFC'!#REF!
Name _DAT18: #REF!
Name _DAT19: '[4]BASE PFC'!#REF!
Name _DAT2: #REF!
Name _DAT3: #REF!
Name _DAT4: #REF!
Name _DAT5: #REF!
Name _DAT5: '[4]BASE PFC'!#REF!
Name _DAT6: #REF!
Name _DAT7: #REF!
Name _DAT8: #REF!
Name _DAT9: #REF!
Name _dic1: #REF!
Name _feb1: #REF!
Name _gen1: #REF!
Name _giu1: #REF!
Name _int01: [0]!_int01
Name _LAC11: #REF!
Name _LAC12: #REF!

Sheet Grafico
B1: Geral - Manutenção
B2: Índice de Execução de Preventivas - Real 16/17 e Meta 16/17

Sheet Dados
A1: Índice Execução Preventivas - Fab. 04
A3: MESES | B3: Bdg 04/05 | C3: Bdg 05/06 | D3: Bdg 06/07 | E3: Bdg 07/08 | F3: Bdg 08/09 | G3: Bdg 09/10 | H3: Bdg 10/11 | I3: Bdg 11/12 | J3: Bdg 12/13 | K3: Bdg 13/14 | L3: Bdg 14/15 | M3: Bdg 15/16 | N3: 42552 | O3: 42583 | P3: 42614 | Q3: 42644 | R3: 42675 | S3: 42705 | T3: 42736 | U3: 42767 | V3: 42795 | W3: 42826 | X3: 42856 | Y3: 42887 | Z3: Acum. 16/17 | AA3: Meta 16/17
A4: Real 16/17 | N4: 96.2 | O4: 59.5 | P4: 96.7 | Q4: 74.5 | R4: 83.3 | S4: 34 | T4: 67.6 | U4: 33.9
A5: Meta 16/17 | N5: 80 | O5: 80 | P5: 80 | Q5: 80 | R5: 80 | S5: 80 | T5: 80 | U5: 80 | V5: 80 | W5: 80 | X5: 80 | Y5: 80
A6: Acumulado | B6: 96.6 | C6: 94.1 | D6: 97.1 | E6: 97 | F6: 90.5 | G6: 76.7 | H6: 93.1 | I6: 47.4 | J6: 72.9 | K6: 72.8 | L6: 82.3 | M6: 53 | Z6: 66.3 | AA6: 80
A7: Acum Meta | B7: 95 | C7: 96 | D7: 97 | E7: 97 | F7: 97 | G7: 97 | H7: 97 | I7: 97 | J7: 97 | K7: 97 | L7: 80 | M7: 80
A9: Índice Execução Preventivas - Fab. 01
A11: MESES | B11: Bdg 04/05 | C11: Bdg 05/06 | D11: Bdg 06/07 | E11: Bdg 07/08 | F11: Bdg 08/09 | G11: Bdg 09/10 | H11: Bdg 10/11 | I11: Bdg 11/12 | J11: Bdg 12/13 | K11: Bdg 13/14 | L11: Bdg 14/15 | M11: Bdg 15/16 | N11: 42552 | O11: 42583 | P11: 42614 | Q11: 42644 | R11: 42675 | S11: 42705 | T11: 42736 | U11: 42767 | V11: 42795 | W11: 42826 | X11: 42856 | Y11: 42887 | Z11: Acum. 16/17 | AA11: Meta 16/17
A12: Real 16/17 | N12: 81.6 | O12: 29.7 | P12: 98.2 | Q12: 21.9 | R12: 97.6 | S12: 97.7 | T12: 92.5 | U12: 2.1
A13: Meta 16/17 | N13: 80 | O13: 80 | P13: 80 | Q13: 80 | R13: 80 | S13: 80 | T13: 80 | U13: 80 | V13: 80 | W13: 80 | X13: 80 | Y13: 80
A14: Acumulado | B14: 96.2 | C14: 96.7 | D14: 97.3 | E14: 97.4 | F14: 99.1 | G14: 98.7 | H14: 98.4 | I14: 93.5 | J14: 95.9 | K14: 75.4 | L14: 86.8 | M14: 84.3 | Z14: 60.3 | AA14: 80
A15: Acum Meta | B15: 95 | C15: 96 | D15: 97 | E15: 97 | F15: 97 | G15: 97 | H15: 97 | I15: 97 | J15: 97 | K15: 97 | L15: 80 | M15: 80
A17: Índice Execução Preventivas - Fab. 03/10
A19: MESES | B19: Bdg 04/05 | C19: Bdg 05/06 | D19: Bdg 06/07 | E19: Bdg 07/08 | F19: Bdg 08/09 | G19: Bdg 09/10 | H19: Bdg 10/11 | I19: Bdg 11/12 | J19: Bdg 12/13 | K19: Bdg 13/14 | L19: Bdg 14/15 | M19: Bdg 15/16 | N19: 42552 | O19: 42583 | P19: 42614 | Q19: 42644 | R19: 42675 | S19: 42705 | T19: 42736 | U19: 42767 | V19: 42795 | W19: 42826 | X19: 42856 | Y19: 42887 | Z19: Acum. 16/17 | AA19: Meta 16/17
A20: Real 16/17 | N20: 77.4 | O20: 97.1 | P20: 71.8 | Q20: 100 | U20: 21.9
A21: Meta 16/17 | N21: 80 | O21: 80 | P21: 80 | Q21: 80 | R21: 80 | S21: 80 | T21: 80 | U21: 80 | V21: 80 | W21: 80 | X21: 80 | Y21: 80
A22: Acumulado | B22: 96 | C22: 98.1 | D22: 98.5 | E22: 99.2 | F22: 100 | G22: 98.6 | H22: 97.7 | I22: 100 | K22: 100 | L22: 78.9 | M22: 84.7 | Z22: 69.9 | AA22: 80
A23: Acum Meta | B23: 95 | C23: 96 | D23: 97 | E23: 97 | F23: 97 | G23: 97 | H23: 97 | I23: 97 | J23: 97 | K23: 97 | L23: 80 | M23: 80
A25: Índice Execução Preventivas - Solda Conectores
A27: MESES | B27: Bdg 04/05 | C27: Bdg 05/06 | D27: Bdg 06/07 | E27: Bdg 07/08 | F27: Bdg 08/09 | G27: Bdg 09/10 | H27: Bdg 10/11 | I27: Bdg 11/12 | J27: Bdg 12/13 | K27: Bdg 13/14 | L27: Bdg 14/15 | M27: Bdg 15/16 | N27: 42552 | O27: 42583 | P27: 42614 | Q27: 42644 | R27: 42675 | S27: 42705 | T27: 42736 | U27: 42767 | V27: 42795 | W27: 42826 | X27: 42856 | Y27: 42887 | Z27: Acum. 16/17 | AA27: Meta 16/17
A28: Real 16/17 | N28: 76.9 | O28: 83.3 | P28: 100 | Q28: 100 | R28: 66.7 | S28: 100 | T28: 100 | U28: 78.3
A29: Meta 16/17 | N29: 80 | O29: 80 | P29: 80 | Q29: 80 | R29: 80 | S29: 80 | T29: 80 | U29: 80 | V29: 80 | W29: 80 | X29: 80 | Y29: 80
A30: Acumulado | B30: 96 | C30: 98.1 | D30: 98.5 | J30: 100 | K30: 91.1 | L30: 80.7 | M30: 85.1 | Z30: 90.6 | AA30: 80
A31: Acum Meta | B31: 95 | C31: 96 | D31: 97 | J31: 97 | K31: 97 | L31: 80 | M31: 80
A33: Índice Execução Preventivas - Fab. 06
A35: MESES | B35: Bdg 04/05 | C35: Bdg 05/06 | D35: Bdg 06/07 | E35: Bdg 07/08 | F35: Bdg 08/09 | G35: Bdg 09/10 | H35: Bdg 10/11 | I35: Bdg 11/12 | J35: Bdg 12/13 | K35: Bdg 13/14 | L35: Bdg 14/15 | M35: Bdg 15/16 | N35: 42552 | O35: 42583 | P35: 42614 | Q35: 42644 | R35: 42675 | S35: 42705 | T35: 42736 | U35: 42767 | V35: 42795 | W35: 42826 | X35: 42856 | Y35: 42887 | Z35: Acum. 16/17 | AA35: Meta 16/17
A36: Real 16/17 | P36: 0 | T36: 100 | U36: 0
A37: Meta 16/17 | N37: 80 | O37: 80 | P37: 80 | Q37: 80 | R37: 80 | S37: 80 | T37: 80 | U37: 80 | V37: 80 | W37: 80 | X37: 80 | Y37: 80
A38: Acumulado | B38: 95 | C38: 95.5 | D38: 99.5 | E38: 98.9 | F38: 99.4 | G38: 99.4 | H38: 99.1 | I38: 99 | J38: 87.8 | K38: 79.7 | L38: 99.6 | M38: 92.5 | Z38: 45.5 | AA38: 80
A39: Acum Meta | B39: 95 | C39: 96 | D39: 97 | E39: 97 | F39: 97 | G39: 97 | H39: 97 | I39: 97 | J39: 97 | K39: 97 | L39: 80 | M39: 80
A41: Índice Execução Preventivas - Toto
A43: MESES | B43: Bdg 04/05 | C43: Bdg 05/06 | D43: Bdg 06/07 | E43: Bdg 07/08 | F43: Bdg 08/09 | G43: Bdg 09/10 | H43: Bdg 10/11 | I43: Bdg 11/12 | J43: Bdg 12/13 | K43: Bdg 13/14 | L43: Bdg 14/15 | M43: Bdg 15/16 | N43: 42552 | O43: 42583 | P43: 42614 | Q43: 42644 | R43: 42675 | S43: 42705 | T43: 42736 | U43: 42767 | V43: 42795 | W43: 42826 | X43: 42856 | Y43: 42887 | Z43: Acum. 16/17 | AA43: Meta 16/17
A44: Real 16/17
A45: Meta 16/17 | N45: 80 | O45: 80 | P45: 80 | Q45: 80 | R45: 80 | S45: 80 | T45: 80 | U45: 80 | V45: 80 | W45: 80 | X45: 80 | Y45: 80
A46: Acumulado | B46: 93.1 | C46: 98.1 | D46: 100 | E46: 99.4 | F46: 99.6 | G46: 100 | H46: 100 | I46: 97.3 | J46: 78 | K46: 89.2 | L46: 95.8 | M46: 97.9 | AA46: 80
A47: Acum Meta | B47: 95 | C47: 96 | D47: 97 | E47: 97 | F47: 97 | G47: 97 | H47: 97 | I47: 97 | J47: 97 | K47: 97 | L47: 80 | M47: 80
A49: Índice Execução Preventivas - Conector
A51: MESES | B51: Bdg 04/05 | C51: Bdg 05/06 | D51: Bdg 06/07 | E51: Bdg 07/08 | F51: Bdg 08/09 | G51: Bdg 09/10 | H51: Bdg 10/11 | I51: Bdg 11/12 | J51: Bdg 12/13 | K51: Bdg 13/14 | L51: Bdg 14/15 | M51: Bdg 15/16 | N51: 42552 | O51: 42583 | P51: 42614 | Q51: 42644 | R51: 42675 | S51: 42705 | T51: 42736 | U51: 42767 | V51: 42795 | W51: 42826 | X51: 42856 | Y51: 42887 | Z51: Acum. 16/17 | AA51: Meta 16/17
A52: Real 16/17 | N52: 33.3 | O52: 100 | P52: 61.5 | Q52: 92.3 | R52: 100 | S52: 20 | T52: 72.7 | U52: 100
A53: Meta 16/17 | N53: 80 | O53: 80 | P53: 80 | Q53: 80 | R53: 80 | S53: 80 | T53: 80 | U53: 80 | V53: 80 | W53: 80 | X53: 80 | Y53: 80
...

Sheet Grafico NEXE
B1: Geral - Manutenção
B2: Total Ots PM01 / PM02 x Encerradas "Não Executar" (NEXE) - Bdg 16/17

Sheet Base Execução Preventivas
D1: =SUBTOTAL(3,DATA4) -> 863
A2: Grp.plnj.PM | B2: CenTrab respon. | C2: Tipo de ordem | D2: Ordem | E2: Texto breve | F2: Status sistema | G2: Loc.instalação | H2: Tipo ativid.PM | I2: Especialidade | J2: Data-base fim | K2: Dt.referência | L2: Dt.real fim
A3: CF2 | B3: CFCOPD01 | C3: PM01 | D3: 10104924784 | E3: FI-INSPEÇÃO HIDRÁULICA MENSAL (1M) | F3: LIB IMPR CAPC NOLQ SCDM | G3: CORJ-CPED-LAER-MA01 | H3: NIM | I3: Mecanica | J3: 42788 | K3: 42788
A4: CF2 | B4: CFCOPD01 | C4: PM01 | D4: 10104932221 | E4: FI - INSP. MEC. CHILLER METALPLAN (1M) | F4: LIB IMPR CAPC NOLQ SCDM | G4: CORJ-CPED-LAPE-MT01 | H4: NIM | I4: Mecanica | J4: 42794 | K4: 42794
A5: CF2 | B5: CFCOPD03 | C5: PM01 | D5: 10104932213 | E5: FI - INSP. MEC. COMPRESSOR DE AR (1M) | F5: ENTE CONF IMPR CAPC MOME NOLQ SCDM | G5: CORJ-CPED-SECE-CO01 | H5: NIM | I5: Mecanica | J5: 42790 | K5: 42790 | L5: 42781
A6: CF2 | B6: CFCOPD03 | C6: PM01 | D6: 10104925721 | E6: FI - INSP. SUBSTAÇÃO PRONCIPAL (1M) | F6: LIB IMPR CAPC NOLQ SCDM | G6: CORJ-CPED-SECE-IF01 | H6: NIE | I6: Eletrica | J6: 42789 | K6: 42789
A7: CF2 | B7: CFCOPD03 | C7: PM01 | D7: 10104949048 | E7: FI - INSP. LIMPEZA DA SUBSTAÇÃO (1M) | F7: LIB IMPR CAPC NOLQ SCDM | G7: CORJ-CPED-SECE-IF01 | H7: NIE | I7: Eletrica | J7: 42786 | K7: 42786
A8: CF2 | B8: CFCOPD03 | C8: PM01 | D8: 10104925735 | E8: FI - Inspeção Painel MT Schneider (1M) | F8: LIB IMPR CAPC NOLQ SCDM | G8: CORJ-CPED-SECE-SB01 | H8: NIE | I8: Eletrica | J8: 42789 | K8: 42789
A9: CF2 | B9: CFCOPD03 | C9: PM01 | D9: 10104925731 | E9: FI - INSPEÇÃO POWER CENTER (1M) | F9: LIB IMPR CAPC NOLQ SCDM | G9: CORJ-CPED-SECE-SB02-PC1 | H9: NIE | I9: Eletrica | J9: 42789 | K9: 42789
A10: CF2 | B10: CFCOPD03 | C10: PM01 | D10: 10104925722 | E10: FI - INSPEÇÃO PAINEL MT ABB (1M) | F10: LIB IMPR CAPC NOLQ SCDM | G10: CORJ-CPED-SECE-SB02-PD1 | H10: NIE | I10: Eletrica | J10: 42789 | K10: 42789
A11: CF2 | B11: CFCOPD03 | C11: PM01 | D11: 10104925732 | E11: FI - INSPEÇÃO TRANSFORAMADOR MT ABB (1M) | F11: LIB IMPR CAPC NOLQ SCDM | G11: CORJ-CPED-SECE-SB02-TR1 | H11: NIE | I11: Eletrica | J11: 42789 | K11: 42789
A12: CF2 | B12: CFCOPD02 | C12: PM01 | D12: 10104925757 | E12: FI-MEC. PONTE ROLANTE GH 20 t (1M) | F12: LIB IMPR CAPC NOLQ SCDM | G12: CORJ-CPED-TRAN-PR01 | H12: NIM | I12: Mecanica | J12: 42789 | K12: 42789
A13: CF2 | B13: CFCOPD02 | C13: PM01 | D13: 10104925758 | E13: FI-MEC. PONTE ROLANTE GH 16 t (1M) | F13: LIB IMPR CAPC NOLQ SCDM | G13: CORJ-CPED-TRAN-PR02 | H13: NIE | I13: Eletrica | J13: 42789 | K13: 42789
A14: CF2 | B14: CFCOPD01 | C14: PM02 | D14: 10104925754 | E14: FP-PREVENTIVA ELÉTRICA MENSAL (1M) | F14: ABER IMPR CAPC DMNV SCDM | G14: CORJ-CPED-LAER-MA01 | H14: NIE | I14: Eletrica | J14: 42789 | K14: 42789
A15: CF2 | B15: CFCOPD01 | C15: PM02 | D15: 10104925880 | E15: FP-PREVENTIVA MECÂNICA MENSAL (1M) | F15: ABER IMPR CAPC DMNV SCDM | G15: CORJ-CPED-LAER-MA01 | H15: NIM | I15: Mecanica | J15: 42789 | K15: 42789
A16: CF2 | B16: CFCOPD01 | C16: PM02 | D16: 10104923811 | E16: FP-PREVENTIVA ELÉTRICA SEMESTRAL (6M) | F16: ABER IMPR CAPC DMNV SCDM | G16: CORJ-CPED-LAER-MA01 | H16: NIE | I16: Eletrica | J16: 42788 | K16: 42788
A17: CF2 | B17: CFCOPD01 | C17: PM02 | D17: 10104930949 | E17: FE-MÁQUINA FADIGA RESSONANTE (3M) | F17: ABER IMPR CAPC DMNV SCDM | G17: CORJ-CPED-LAER-MA02 | H17: NGE | I17: Eletrica | J17: 42793 | K17: 42793
... A19: CF2 | B19: CFCOPD01 | C19: PM02 | D19: 10104928569 | E19: FE-GUINDASTE GIRATORIO STAHL 5T (1M) | F19: ABER IMPR CAPC DMNV SCDM | G19: CORJ-CPED-LAER-MB01-GU1 | H19: NGE | I19: Eletrica | J19: 42791 | K19: 42791
A20: CF2 | B20: CFCOPD01 | C20: PM02 | D20: 10104930967 | E20: FE-MÁQUINA DE TRAÇÃO MTS (3M) | F20: ENTE CONF IMPR CAPC NOLQ SCDM | G20: CORJ-CPED-LAPE-MT01 | H20: NGE | I20: Eletrica | J20: 42790 | K20: 42790 | L20: 42789
A21: CF2 | B21: CFCOPD01 | C21: PM02 | D21: 10104930981 | E21: FE-POLITRIZ SEMI AUTOMÁTIZADO PRESI (3M) | F21: ABER IMPR CAPC DMNV SCDM | G21: CORJ-CPED-LAPE-PO01 | H21: NGE | I21: Eletrica | J21: 42793 | K21: 42793
A22: CF2 | B22: CFCOPD01 | C22: PM02 | D22: 10104930968 | E22: FE-ESTAÇÃO SOLDAGEM MULTI PROCESSO (3M) | F22: ABER IMPR CAPC DMNV SCDM | G22: CORJ-CPED-LASO-ES03 | H22: NGE | I22: Eletrica | J22: 42793 | K22: 42793
A23: CF2 | B23: CFCOPD01 | C23: PM02 | D23: 10104930950 | E23: FE-ESTAÇÃO DE SOLDAGEM AUTO (ROBÔ) (3M) | F23: ENTE CONF IMPR CAPC NOLQ SCDM | G23: CORJ-CPED-LASO-ES05 | H23: NGE | I23: Eletrica | J23: 42790 | K23: 42790 | L23: 42789
A24: CF2 | B24: CFCOPD01 | C24: PM02 | D24: 10104928568 | E24: FE-GUINDASTE GIRATÓRIO STAHL 3,5T (1M) | F24: ENTE CONF IMPR CAPC NOLQ SCDM | G24: CORJ-CPED-LASO-SC02-GU1 | H24: NGE | I24: Eletrica | J24: 42790 | K24: 42790 | L24: 42789
A25: CF2 | B25: CFCOPD03 | C25: PM02 | D25: 10104932237 | E25: FP - PREV. SISTEMA AR COND. CENTRAL (1M) | F25: ABER IMPR CAPC DMNV SCDM | G25: CORJ-CPED-SECE-AC01 | H25: NIM | I25: Mecanica | J25: 42794 | K25: 42794
A26: CF2 | B26: CFCOPD03 | C26: PM02 | D26: 10104928512 | E26: FP - MANUT. PREV. ELEVADOR PESSOAL (1M) | F26: ABER IMPR CAPC DMNV SCDM | G26: CORJ-CPED-SECE-EL01 | H26: NIM | I26: Mecanica | J26: 42791 | K26: 42791
A27: CF2 | B27: CFCOPD03 | C27: PM02 | D27: 10104932236 | E27: FE - PLANO ESPOLETA SIST. COMB INCÊNDIO | F27: ABER IMPR CAPC DMNV SCDM | G27: CORJ-CPED-SECE-RA01-SC1 | H27: NGE | I27: Eletrica | J27: 42794 | K27: 42794
A28: CF2 | B28: CFCOPD02 | C28: PM02 | D28: 10104923810 | E28: FP-MEC.PONTE ROLANTE GH 20 t (6M) | F28: ABER IMPR CAPC DMNV SCDM | G28: CORJ-CPED-TRAN-PR01 | H28: NIM | I28: Mecanica | J28: 42788 | K28: 42788
A29: CF2 | B29: CFCOPD02 | C29: PM02 | D29: 10104928566 | E29: FE-PONTE ROLANTE GH 20 t (1M) | F29: ABER IMPR CAPC DMNV SCDM | G29: CORJ-CPED-TRAN-PR01 | H29: NGE | I29: Eletrica | J29: 42791 | K29: 42791
A30: CF2 | B30: CFCOPD02 | C30: PM02 | D30: 10104923853 | E30: FP-ELE. PONTE ROLANTE GH 20 t (6M) | F30: ABER IMPR CAPC DMNV SCDM | G30: CORJ-CPED-TRAN-PR01 | H30: NIE | I30: Eletrica | J30: 42788 | K30: 42788
A31: CF2 | B31: CFCOPD02 | C31: PM02 | D31: 10104924798 | E31: FP-MEC. PONTE ROLANTE GH 20 t (3M) | F31: ABER IMPR CAPC DMNV SCDM | G31: CORJ-CPED-TRAN-PR01 | H31: NIM | I31: Mecanica | J31: 42788 | K31: 42788
A32: CF2 | B32: CFCOPD02 | C32: PM02 | D32: 10104928567 | E32: FE - PONTE ROLANTE GH 16 t (1M) | F32: ABER IMPR CAPC DMNV SCDM | G32: CORJ-CPED-TRAN-PR02 | H32: NGE | I32: Eletrica | J32: 42791 | K32: 42791
A33: CF2 | B33: CFCOPD03 | C33: PM02 | D33: 10104932222 | E33: FP- PREVENTIVA MEC CARRETA DE TUBOS (3M) | F33: ABER IMPR CAPC DMNV SCDM | G33: CORJ-CPED-VEIC-CR01 | H33: NIM | I33: Mecanica | J33: 42794 | K33: 42794
A34: CF2 | B34: CFCOPD03 | C34: PM02 | D34: 10104932214 | E34: FP- PREV. MEC. EMPILHADEIRA CLARK (1M) | F34: ABER IMPR CAPC DMNV SCDM | G34: CORJ-CPED-VEIC-EM01 | H34: NIM | I34: Mecanica | J34: 42794 | K34: 42794
A35: CF4 | B35: CFCOGM06 | C35: PM01 | D35: 10104935238 | E35: FIP -MECÂNICA CARRO JATO INT (SEMESTRAL) | F35: ENTE CONF CAPC NOLQ SCDM | G35: COIN-REVS-REV3-PROC-CA1 | H35: NIM | I35: Mecanica | J35: 42780 | K35: 42790 | L35: 42790
A36: CF4 | B36: CFCOGM06 | C36: PM01 | D36: 10104918245 | E36: FIP - ELÉTRICA DO JATO INT (SEMESTRAL) | F36: ENTE CONF CAPC NOLQ SCDM | G36: COIN-REVS-REV3-PROC-CA1 | H36: NIE | I36: Eletrica | J36: 42780 | K36: 42787 | L36: 42787
A37: CF4 | B37: CFCOGM06 | C37: PM01 | D37: 10104916788 | E37: FIP - MECÂNICA PINTURA EXT (SEMESTRAL) | F37: ENTE CONF CAPC NOLQ SCDM | G37: COIN-REVS-REV3-PROC-CA2 | H37: NIM | I37: Mecanica | J37: 42779 | K37: 42790 | L37: 42790
A38: CF4 | B38: CFCOGM06 | C38: PM01 | D38: 10104916787 | E38: FIP - ELÉTRICA PINTURA EXT (SEMESTRAL) | F38: ENTE CONF CAPC NOLQ SCDM | G38: COIN-REVS-REV3-PROC-CA2 | H38: NIE | I38: Eletrica | J38: 42779 | K38: 42787 | L38: 42787
A39: CF4 | B39: CFCOGM06 | C39: PM01 | D39: 10104911396 | E39: FIP - ELÉTRICA MCC REVEST 3 (SEMESTRAL) | F39: ENTE CONF CAPC NOLQ SCDM | G39: COIN-REVS-REV3-PROC-MC1 | H39: NIE | I39: Eletrica | J39: 42774 | K39: 42787 | L39: 42787
A40: CF4 | B40: CFCOGM06 | C40: PM01 | D40: 10104911397 | E40: FIP - ELÉTRICA PAINEL REV 3 (SEMESTRAL) | F40: ENTE CONF CAPC NOLQ SCDM | G40: COIN-REVS-REV3-PROC-PC1 | H40: NIE | I40: Eletrica | J40: 42774 | K40: 42787 | L40: 42787
A41: CF4 | B41: CFCOGM06 | C41: PM01 | D41: 10104916789 | E41: FIP - MECÂNICA PINTURA EXT (SEMESTRAL) | F41: ENTE CONF CAPC NOLQ SCDM | G41: COIN-REVS-REV3-PROC-PI2 | H41: NIM | I41: Mecanica | J41: 42779 | K41: 42790 | L41: 42790
...

Sheet Dados NEXe
A2: Encerradaas NEXE - Fab 04
A4: MESES | B4: 42552 | C4: 42583 | D4: 42614 | E4: 42644 | F4: 42675 | G4: 42705 | H4: 42736 | I4: 42736 | J4: 42795 | K4: 42826 | L4: 42856 | M4: 42887 | N4: Acum. PM01 / PM02 | O4: Acum. Nexe
A5: Total PM01 / PM02 | B5: 197 | C5: 180 | D5: 158 | E5: 236 | F5: 219 | G5: 236 | H5: 171 | I5: =COUNTIFS('Base NEXE '!$A:$A,"CF5",'Base NEXE '!$G:$G,"*MAUO*") -> 147
A6: TotaL Encerrada NEXE (Não Executar) | B6: 64 | C6: 33 | D6: 35 | E6: 28 | F6: 39 | G6: 1 | H6: 27 | I6: =COUNTIFS('Base NEXE '!$A:$A,"CF5",'Base NEXE '!$G:$G,"*MAUO*",'Base NEXE '!$F:$F,"*NEXE*") -> 20
A7: % Acumulada | N7: =SUM(B5:M5) -> 1544 | O7: =SUM(B6:M6) -> 247
A9: Encerradaas NEXE - Fab 01
A11: MESES | B11: 42552 | C11: 42583 | D11: 42614 | E11: 42644 | F11: 42675 | G11: 42705 | H11: 42736 | I11: 42736 | J11: 42795 | K11: 42826 | L11: 42856 | M11: 42887 | N11: Acum. PM01 / PM02 | O11: Acum. Nexe
A12: Total PM01 / PM02 | B12: 136 | C12: 150 | D12: 121 | E12: 151 | F12: 137 | G12: 171 | H12: 120 | I12: =COUNTIFS('Base NEXE '!$A:$A,"CF6",'Base NEXE '!$G:$G,"*MAER*") -> 142
A13: TotaL Encerrada NEXE (Não Executar) | B13: 0 | C13: 4 | D13: 10 | E13: 4 | F13: 7 | G13: 16 | H13: 27 | I13: =COUNTIFS('Base NEXE '!$A:$A,"CF6",'Base NEXE '!$G:$G,"*MAER*",'Base NEXE '!$F:$F,"*NEXE*") -> 0
A14: % Acumulada | N14: =SUM(B12:M12) -> 1128 | O14: =SUM(B13:M13) -> 68
A16: Encerradaas NEXE - Fab 10
A18: MESES | B18: 42552 | C18: 42583 | D18: 42614 | E18: 42644 | F18: 42675 | G18: 42705 | H18: 42736 | I18: 42736 | J18: 42795 | K18: 42826 | L18: 42856 | M18: 42887 | N18: Acum. PM01 / PM02 | O18: Acum. Nexe
A19: Total PM01 / PM02 | B19: 60 | C19: 40 | D19: 56 | E19: 9 | F19: 0 | G19: 0 | H19: 0 | I19: =COUNTIFS('Base NEXE '!$A:$A,"CF6",'Base NEXE '!$G:$G,"*MAHE*") -> 32
A20: TotaL Encerrada NEXE (Não Executar) | B20: 7 | C20: 6 | D20: 17 | E20: 4 | F20: 0 | G20: 0 | H20: 0 | I20: =COUNTIFS('Base NEXE '!$A:$A,"CF6",'Base NEXE '!$G:$G,"*MAHE*",'Base NEXE '!$F:$F,"*NEXE*") -> 0
A21: % Acumulada | N21: =SUM(B19:M19) -> 197 | O21: =SUM(B20:M20) -> 34
A23: Encerradaas NEXE - SCON
A25: MESES | B25: 42552 | C25: 42583 | D25: 42614 | E25: 42644 | F25: 42675 | G25: 42705 | H25: 42736 | I25: 42736 | J25: 42795 | K25: 42826 | L25: 42856 | M25: 42887 | N25: Acum. PM01 / PM02 | O25: Acum. Nexe
A26: Total PM01 / PM02 | B26: 13 | C26: 14 | D26: 16 | E26: 16 | F26: 8 | G26: 27 | H26: 16 | I26: =COUNTIFS('Base NEXE '!$A:$A,"CF6",'Base NEXE '!$G:$G,"*SCON*") -> 23
A27: TotaL Encerrada NEXE (Não Executar) | B27: 0 | C27: 2 | D27: 0 | E27: 0 | F27: 2 | G27: 0 | H27: 2 | I27: =COUNTIFS('Base NEXE '!$A:$A,"CF6",'Base NEXE '!$G:$G,"*SCON*",'Base NEXE '!$F:$F,"*NEXE*") -> 0
A28: % Acumulada | N28: =SUM(B26:M26) -> 133 | O28: =SUM(B27:M27) -> 6
A30: Encerradaas NEXE - Fab 06
A32: MESES | B32: 42552 | C32: 42583 | D32: 42614 | E32: 42644 | F32: 42675 | G32: 42705 | H32: 42736 | I32: 42736 | J32: 42795 | K32: 42826 | L32: 42856 | M32: 42887 | N32: Acum. PM01 / PM02 | O32: Acum. Nexe
A33: Total PM01 / PM02 | B33: 0 | C33: 0 | D33: 1 | E33: 0 | F33: 0 | G33: 1 | H33: 5 | I33: =COUNTIFS('Base NEXE '!$A:$A,"CF7",'Base NEXE '!$G:$G,"*ROSC*") -> 9
A34: TotaL Encerrada NEXE (Não Executar) | B34: 0 | C34: 0 | D34: 0 | E34: 0 | F34: 0 | G34: 1 | H34: 0 | I34: =COUNTIFS('Base NEXE '!$A:$A,"CF7",'Base NEXE '!$G:$G,"*ROSC*",'Base NEXE '!$F:$F,"*NEXE*") -> 4
A35: % Acumulada | N35: =SUM(B33:M33) -> 16 | O35: =SUM(B34:M34) -> 5
A37: Encerradaas NEXE - Toto
A39: MESES | B39: 42552 | C39: 42583 | D39: 42614 | E39: 42644 | F39: 42675 | G39: 42705 | H39: 42736 | I39: 42736 | J39: 42795 | K39: 42826 | L39: 42856 | M39: 42887 | N39: Acum. PM01 / PM02 | O39: Acum. Nexe
A40: Total PM01 / PM02 | B40: 0 | C40: 0 | D40: 0 | E40: 0 | F40: 0 | G40: 0 | H40: 0 | I40: =COUNTIFS('Base NEXE '!$A:$A,"CF7",'Base NEXE '!$G:$G,"*TOTO*") -> 0
A41: TotaL Encerrada NEXE (Não Executar) | B41: 0 | C41: 0 | D41: 0 | E41: 0 | F41: 0 | G41: 0 | H41: 0 | I41: =COUNTIFS('Base NEXE '!$A:$A,"CF7",'Base NEXE '!$G:$G,"*TOTO*",'Base NEXE '!$F:$F,"*NEXE*") -> 0
A42: % Acumulada | N42: =SUM(B40:M40) -> 0 | O42: =SUM(B41:M41) -> 0
A44: Encerradaas NEXE - Rev 03
A46: MESES | B46: 42552 | C46: 42583 | D46: 42614 | E46: 42644 | F46: 42675 | G46: 42705 | H46: 42736 | I46: 42736 | J46: 42795 | K46: 42826 | L46: 42856 | M46: 42887 | N46: Acum. PM01 / PM02 | O46: Acum. Nexe
A47: Total PM01 / PM02 | B47: 25 | C47: 22 | D47: 22 | E47: 19 | F47: 22 | G47: 18 | H47: 24 | I47: =COUNTIFS('Base NEXE '!$A:$A,"CF4",'Base NEXE '!$G:$G,"*REV3*") -> 25
A48: TotaL Encerrada NEXE (Não Executar) | B48: 4 | C48: 17 | D48: 17 | E48: 17 | F48: 17 | G48: 18 | H48: 18 | I48: =COUNTIFS('Base NEXE '!$A:$A,"CF4",'Base NEXE '!$G:$G,"*REV3*",'Base NEXE '!$F:$F,"*NEXE*") -> 17
A49: % Acumulada | N49: =SUM(B47:M47) -> 177 | O49: =SUM(B48:M48) -> 125
A51: Encerradaas NEXE - Rev 04
A53: MESES | B53: 42552 | C53: 42583 | D53: 42614 | E53: 42644 | F53: 42675 | G53: 42705 | H53: 42736 | I53: 42736 | J53: 42795 | K53: 42826 | L53: 42856 | M53: 42887 | N53: Acum. PM01 / PM02 | O53: Acum. Nexe
A54: Total PM01 / PM02 | B54: 75 | C54: 59 | D54: 66 | E54: 52 | F54: 59 | G54: 53 | H54: 71 | I54: =COUNTIFS('Base NEXE '!$A:$A,"CF4",'Base NEXE '!$G:$G,"*REV4*") -> 56
A55: TotaL Encerrada NEXE (Não Executar) | B55: 30 | C55: 17 | D55: 24 | E55: 16 | F55: 27 | G55: 16 | H55: 33 | I55: =COUNTIFS('Base NEXE '!$A:$A,"CF4",'Base NEXE '!$G:$G,"*REV4*",'Base NEXE '!$F:$F,"*NEXE*") -> 18
A56: % Acumulada | N56: =SUM(B54:M54) -> 491 | O56: =SUM(B55:M55) -> 181
...

Sheet Base NEXE 
D1: =SUBTOTAL(3,D3:D2334) -> 977
A2: Grp.plnj.PM | B2: CenTrab respon. | C2: Tipo de ordem | D2: Ordem | E2: Texto breve | F2: Status sistema | G2: Loc.instalação | H2: Tipo ativid.PM | I2: Data-base fim | J2: Dt.referência | K2: Dt.real fim
A3: CF2 | B3: CFCOPD01 | C3: PM01 | D3: 10104924784 | E3: FI-INSPEÇÃO HIDRÁULICA MENSAL (1M) | F3: LIB IMPR CAPC NOLQ SCDM | G3: CORJ-CPED-LAER-MA01 | H3: NIM | I3: 42788 | J3: 42788
A4: CF2 | B4: CFCOPD01 | C4: PM01 | D4: 10104932221 | E4: FI - INSP. MEC. CHILLER METALPLAN (1M) | F4: LIB IMPR CAPC NOLQ SCDM | G4: CORJ-CPED-LAPE-MT01 | H4: NIM | I4: 42794 | J4: 42794
A5: CF2 | B5: CFCOPD03 | C5: PM01 | D5: 10104932213 | E5: FI - INSP. MEC. COMPRESSOR DE AR (1M) | F5: ENTE CONF IMPR CAPC MOME NOLQ SCDM | G5: CORJ-CPED-SECE-CO01 | H5: NIM | I5: 42790 | J5: 42790 | K5: 42781
A6: CF2 | B6: CFCOPD03 | C6: PM01 | D6: 10104949048 | E6: FI - INSP. LIMPEZA DA SUBSTAÇÃO (1M) | F6: LIB IMPR CAPC NOLQ SCDM | G6: CORJ-CPED-SECE-IF01 | H6: NIE | I6: 42786 | J6: 42786
A7: CF2 | B7: CFCOPD03 | C7: PM01 | D7: 10104925721 | E7: FI - INSP. SUBSTAÇÃO PRONCIPAL (1M) | F7: LIB IMPR CAPC NOLQ SCDM | G7: CORJ-CPED-SECE-IF01 | H7: NIE | I7: 42789 | J7: 42789
A8: CF2 | B8: CFCOPD03 | C8: PM01 | D8: 10104925735 | E8: FI - Inspeção Painel MT Schneider (1M) | F8: LIB IMPR CAPC NOLQ SCDM | G8: CORJ-CPED-SECE-SB01 | H8: NIE | I8: 42789 | J8: 42789
A9: CF2 | B9: CFCOPD03 | C9: PM01 | D9: 10104925731 | E9: FI - INSPEÇÃO POWER CENTER (1M) | F9: LIB IMPR CAPC NOLQ SCDM | G9: CORJ-CPED-SECE-SB02-PC1 | H9: NIE | I9: 42789 | J9: 42789
A10: CF2 | B10: CFCOPD03 | C10: PM01 | D10: 10104925722 | E10: FI - INSPEÇÃO PAINEL MT ABB (1M) | F10: LIB IMPR CAPC NOLQ SCDM | G10: CORJ-CPED-SECE-SB02-PD1 | H10: NIE | I10: 42789 | J10: 42789
A11: CF2 | B11: CFCOPD03 | C11: PM01 | D11: 10104925732 | E11: FI - INSPEÇÃO TRANSFORAMADOR MT ABB (1M) | F11: LIB IMPR CAPC NOLQ SCDM | G11: CORJ-CPED-SECE-SB02-TR1 | H11: NIE | I11: 42789 | J11: 42789
A12: CF2 | B12: CFCOPD02 | C12: PM01 | D12: 10104925757 | E12: FI-MEC. PONTE ROLANTE GH 20 t (1M) | F12: LIB IMPR CAPC NOLQ SCDM | G12: CORJ-CPED-TRAN-PR01 | H12: NIM | I12: 42789 | J12: 42789
A13: CF2 | B13: CFCOPD02 | C13: PM01 | D13: 10104925758 | E13: FI-MEC. PONTE ROLANTE GH 16 t (1M) | F13: LIB IMPR CAPC NOLQ SCDM | G13: CORJ-CPED-TRAN-PR02 | H13: NIE | I13: 42789 | J13: 42789
A14: CF2 | B14: CFCOPD01 | C14: PM02 | D14: 10104925880 | E14: FP-PREVENTIVA MECÂNICA MENSAL (1M) | F14: ABER IMPR CAPC DMNV SCDM | G14: CORJ-CPED-LAER-MA01 | H14: NIM | I14: 42789 | J14: 42789
A15: CF2 | B15: CFCOPD01 | C15: PM02 | D15: 10104925754 | E15: FP-PREVENTIVA ELÉTRICA MENSAL (1M) | F15: ABER IMPR CAPC DMNV SCDM | G15: CORJ-CPED-LAER-MA01 | H15: NIE | I15: 42789 | J15: 42789
A16: CF2 | B16: CFCOPD01 | C16: PM02 | D16: 10104923811 | E16: FP-PREVENTIVA ELÉTRICA SEMESTRAL (6M) | F16: ABER IMPR CAPC DMNV SCDM | G16: CORJ-CPED-LAER-MA01 | H16: NIE | I16: 42788 | J16: 42788
A17: CF2 | B17: CFCOPD01 | C17: PM02 | D17: 10104930949 | E17: FE-MÁQUINA FADIGA RESSONANTE (3M) | F17: ABER IMPR CAPC DMNV SCDM | G17: CORJ-CPED-LAER-MA02 | H17: NGE | I17: 42793 | J17: 42793
... A19: CF2 | B19: CFCOPD01 | C19: PM02 | D19: 10104928569 | E19: FE-GUINDASTE GIRATORIO STAHL 5T (1M) | F19: ABER IMPR CAPC DMNV SCDM | G19: CORJ-CPED-LAER-MB01-GU1 | H19: NGE | I19: 42791 | J19: 42791
A20: CF2 | B20: CFCOPD01 | C20: PM02 | D20: 10104930967 | E20: FE-MÁQUINA DE TRAÇÃO MTS (3M) | F20: ENTE CONF IMPR CAPC NOLQ SCDM | G20: CORJ-CPED-LAPE-MT01 | H20: NGE | I20: 42790 | J20: 42790 | K20: 42789
A21: CF2 | B21: CFCOPD01 | C21: PM02 | D21: 10104930981 | E21: FE-POLITRIZ SEMI AUTOMÁTIZADO PRESI (3M) | F21: ABER IMPR CAPC DMNV SCDM | G21: CORJ-CPED-LAPE-PO01 | H21: NGE | I21: 42793 | J21: 42793
A22: CF2 | B22: CFCOPD01 | C22: PM02 | D22: 10104930968 | E22: FE-ESTAÇÃO SOLDAGEM MULTI PROCESSO (3M) | F22: ABER IMPR CAPC DMNV SCDM | G22: CORJ-CPED-LASO-ES03 | H22: NGE | I22: 42793 | J22: 42793
A23: CF2 | B23: CFCOPD01 | C23: PM02 | D23: 10104930950 | E23: FE-ESTAÇÃO DE SOLDAGEM AUTO (ROBÔ) (3M) | F23: ENTE CONF IMPR CAPC NOLQ SCDM | G23: CORJ-CPED-LASO-ES05 | H23: NGE | I23: 42790 | J23: 42790 | K23: 42789
A24: CF2 | B24: CFCOPD01 | C24: PM02 | D24: 10104928568 | E24: FE-GUINDASTE GIRATÓRIO STAHL 3,5T (1M) | F24: ENTE CONF IMPR CAPC NOLQ SCDM | G24: CORJ-CPED-LASO-SC02-GU1 | H24: NGE | I24: 42790 | J24: 42790 | K24: 42789
A25: CF2 | B25: CFCOPD03 | C25: PM02 | D25: 10104932237 | E25: FP - PREV. SISTEMA AR COND. CENTRAL (1M) | F25: ABER IMPR CAPC DMNV SCDM | G25: CORJ-CPED-SECE-AC01 | H25: NIM | I25: 42794 | J25: 42794
A26: CF2 | B26: CFCOPD03 | C26: PM02 | D26: 10104928512 | E26: FP - MANUT. PREV. ELEVADOR PESSOAL (1M) | F26: ABER IMPR CAPC DMNV SCDM | G26: CORJ-CPED-SECE-EL01 | H26: NIM | I26: 42791 | J26: 42791
A27: CF2 | B27: CFCOPD03 | C27: PM02 | D27: 10104932236 | E27: FE - PLANO ESPOLETA SIST. COMB INCÊNDIO | F27: ABER IMPR CAPC DMNV SCDM | G27: CORJ-CPED-SECE-RA01-SC1 | H27: NGE | I27: 42794 | J27: 42794
A28: CF2 | B28: CFCOPD02 | C28: PM02 | D28: 10104924798 | E28: FP-MEC. PONTE ROLANTE GH 20 t (3M) | F28: ABER IMPR CAPC DMNV SCDM | G28: CORJ-CPED-TRAN-PR01 | H28: NIM | I28: 42788 | J28: 42788
A29: CF2 | B29: CFCOPD02 | C29: PM02 | D29: 10104928566 | E29: FE-PONTE ROLANTE GH 20 t (1M) | F29: ABER IMPR CAPC DMNV SCDM | G29: CORJ-CPED-TRAN-PR01 | H29: NGE | I29: 42791 | J29: 42791
A30: CF2 | B30: CFCOPD02 | C30: PM02 | D30: 10104923810 | E30: FP-MEC.PONTE ROLANTE GH 20 t (6M) | F30: ABER IMPR CAPC DMNV SCDM | G30: CORJ-CPED-TRAN-PR01 | H30: NIM | I30: 42788 | J30: 42788
A31: CF2 | B31: CFCOPD02 | C31: PM02 | D31: 10104923853 | E31: FP-ELE. PONTE ROLANTE GH 20 t (6M) | F31: ABER IMPR CAPC DMNV SCDM | G31: CORJ-CPED-TRAN-PR01 | H31: NIE | I31: 42788 | J31: 42788
A32: CF2 | B32: CFCOPD02 | C32: PM02 | D32: 10104928567 | E32: FE - PONTE ROLANTE GH 16 t (1M) | F32: ABER IMPR CAPC DMNV SCDM | G32: CORJ-CPED-TRAN-PR02 | H32: NGE | I32: 42791 | J32: 42791
A33: CF2 | B33: CFCOPD03 | C33: PM02 | D33: 10104932222 | E33: FP- PREVENTIVA MEC CARRETA DE TUBOS (3M) | F33: ABER IMPR CAPC DMNV SCDM | G33: CORJ-CPED-VEIC-CR01 | H33: NIM | I33: 42794 | J33: 42794
A34: CF2 | B34: CFCOPD03 | C34: PM02 | D34: 10104932214 | E34: FP- PREV. MEC. EMPILHADEIRA CLARK (1M) | F34: ABER IMPR CAPC DMNV SCDM | G34: CORJ-CPED-VEIC-EM01 | H34: NIM | I34: 42794 | J34: 42794
A35: CF4 | B35: CFCOGM06 | C35: PM01 | D35: 10104935238 | E35: FIP -MECÂNICA CARRO JATO INT (SEMESTRAL) | F35: ENTE CONF CAPC NOLQ SCDM | G35: COIN-REVS-REV3-PROC-CA1 | H35: NIM | I35: 42780 | J35: 42790 | K35: 42790
A36: CF4 | B36: CFCOGM06 | C36: PM01 | D36: 10104918245 | E36: FIP - ELÉTRICA DO JATO INT (SEMESTRAL) | F36: ENTE CONF CAPC NOLQ SCDM | G36: COIN-REVS-REV3-PROC-CA1 | H36: NIE | I36: 42780 | J36: 42787 | K36: 42787
A37: CF4 | B37: CFCOGM06 | C37: PM01 | D37: 10104916787 | E37: FIP - ELÉTRICA PINTURA EXT (SEMESTRAL) | F37: ENTE CONF CAPC NOLQ SCDM | G37: COIN-REVS-REV3-PROC-CA2 | H37: NIE | I37: 42779 | J37: 42787 | K37: 42787
A38: CF4 | B38: CFCOGM06 | C38: PM01 | D38: 10104916788 | E38: FIP - MECÂNICA PINTURA EXT (SEMESTRAL) | F38: ENTE CONF CAPC NOLQ SCDM | G38: COIN-REVS-REV3-PROC-CA2 | H38: NIM | I38: 42779 | J38: 42790 | K38: 42790
A39: CF4 | B39: CFCOGM06 | C39: PM01 | D39: 10104911396 | E39: FIP - ELÉTRICA MCC REVEST 3 (SEMESTRAL) | F39: ENTE CONF CAPC NOLQ SCDM | G39: COIN-REVS-REV3-PROC-MC1 | H39: NIE | I39: 42774 | J39: 42787 | K39: 42787
A40: CF4 | B40: CFCOGM06 | C40: PM01 | D40: 10104911397 | E40: FIP - ELÉTRICA PAINEL REV 3 (SEMESTRAL) | F40: ENTE CONF CAPC NOLQ SCDM | G40: COIN-REVS-REV3-PROC-PC1 | H40: NIE | I40: 42774 | J40: 42787 | K40: 42787
A41: CF4 | B41: CFCOGM06 | C41: PM01 | D41: 10104916789 | E41: FIP - MECÂNICA PINTURA EXT (SEMESTRAL) | F41: ENTE CONF CAPC NOLQ SCDM | G41: COIN-REVS-REV3-PROC-PI2 | H41: NIM | I41: 42779 | J41: 42790 | K41: 42790
...

Sheet Observações
A1: Indice de Execução de Preventivas
A2: Mês | B2: Area | C2: Indice % | D2: Motivo da Variação (Indice de Preventivas) | E2: Ação | F2: Responsável
A5: Jul 16 | B5: Conector | C5: 33.3
A6: Jul 16 | B6: Rev 03 | C6: 61.9
A7: Jul 16 | B7: Rev Ext. | C7: 0
A8: Jul 16 | B8: Pontes | C8: 39.8 | D8: HH do plano superior em 50% À M.O. disponivel. Pessoal trabalhando em manutenção preventiva PM11 | E8: Revissão do plano
A9: Jul 16 | B9: Veiculos | C9: 14.3
A10: Jul 16 | B10: CORJ | C10: 20
A11: Ago 16 | B11: Fab 04 | C11: 59.5 | D11: Preventivas sendo executadas com o 2 recursos do Grupo de RP em 1 semana da (01 a 06/08), Luiz Salgado e Ricardo Neves. Essa mão de obra não foi suficiente para garantir a execução das prevenivas mensais. Tivemos que reforçar o time com o GMB, deixando algumas inspeções sem execução.
A12: Ago 16 | B12: Fab 01 | C12: 29.7
A13: Ago 16 | B13: Pontes | C13: 38.5 | D13: HH do plano superior em 50% À M.O. disponivel. Pessoal trabalhando em manutenção preventiva PM11 | E13: Revissão do plano
A14: Ago 16 | B14: Veiculos | C14: 0
A15: Ago 16 | B15: Corj | C15: 22.2
A16: Set 16 | B16: Conector | C16: 61.5
A17: Set 16 | B17: Veiculos | C17: 0
A18: Out 16 | B18: Fab 01 | C18: 21.9
A19: Out 16 | B19: Pontes | C19: 18.7 | D19: HH do plano superior em 50% À M.O. disponivel. Funcionario de Férias Pessoal trabalhando em manutenção preventiva PM11 | E19: Revissão do plano
A20: Out 16 | B20: Veiculos | C20: 0
A21: Nov 16 | B21: Conector | C21: 66.7
A22: Nov 16 | B22: Pontes | C22: 24.7 | D22: HH do plano superior em 50% À M.O. disponivel. Pessoal trabalhando em manutenção preventiva PM11 | E22: Revissão do plano
A23: Nov 16 | B23: NDT | C23: 43.3
A24: Dez 16 | B24: Fab 04 | C24: 34 | D24: As fichas de inspeção elétrica da Formação não foram executadas por o recurdo estava no 3ºT, assim como as fichas de inspeção das Soldas Interas e Externas. O mês foi curto devido à ponte entre Natal e Ano Novo. As preventivas abertas não foram acertadas a tempo da geração do relatório, penalizando o indicador. Fichas anuais, semestrais estavam com a programação no mês, não foram reprogramadas e impactando também no indicador.
A25: Dez 16 | B25: Conector | C25: 20
A26: Dez 16 | B26: Pontes | C26: 10.1 | D26: HH do plano superior em 75% À M.O. disponivel. Funcionario de Férias. Pessoal trabalhando em manutenção preventiva PM11 | E26: Revissão do plano
A27: Dez 16 | B27: NDT | C27: 6.3
A28: Dez 16 | B28: Veiculos | C28: 42.9
A29: Jan 17 | B29: Rev Ext. | C29: 55.8
A30: Jan 17 | B30: NDT | C30: 41.4 | D30: HH do plano superior em 50% À M.O. disponivel. Pessoal trabalhando em manutenção preventiva PM11 | E30: Revissão do plano. Reorganização da equipe de trabalho.
A31: Jan 17 | B31: R & D | C31: 58.8
A32: Fev 17 | B32: Fab 04 | C32: 33.9
A33: Fev 17 | B33: Fab 01 | C33: 2.1
A34: Fev 17 | B34: Fab 10 | C34: 21.9
A35: Fev 17 | B35: Fab 06 | C35: 0
A36: Fev 17 | B36: Rev. Ext | C36: 39.5
A37: Fev 17 | B37: NDT | C37: 6.1
A38: Fev 17 | B38: R & D | C38: 12.5
